 > Completed: ACL Indoor - ACL Indoor (1 matches)
  > Completed: Friendlies - National Teams. Women (1 matches)
  > Completed: Brazil - Campeonato Gaucho. Division 2 (1 matches)
  > Completed: Club Friendlies - Club Friendlies (17 matches)
  > Completed: Brazil - Brazil Championship U20 (3 matches)
  > Completed: Division 4х4 - Division 4х4 (1 matches)
Saved Club World Cup.json
Saved Club Friendlies.json
Saved Latvia.json
Saved Svenska Cupen.json
Saved Friendlies.json
Saved Brazil.json
Saved Finland.json
Saved Ireland Championship U20.json
Saved Student League 2.json
Saved BudnesLiga LFL 5x5.json
Saved USSR.json
Saved ACL Indoor.json
Saved Division 4х4.json
Saved Short.json
Saved Subsoccer.json
Saved FIFA 25.json
Saved FIFA 23.json
Cycle number 25 completed
Traceback (most recent call last):
  File "C:\Users\HP\Desktop\Arbitrage Betting\.venv\Lib\site-packages\urllib3\connection.py", line 198, in _new_conn
    sock = connection.create_connection(
        (self._dns_host, self.port),
    ...<2 lines>...
        socket_options=self.socket_options,
    )
  File "C:\Users\HP\Desktop\Arbitrage Betting\.venv\Lib\site-packages\urllib3\util\connection.py", line 60, in create_connection
    for res in socket.getaddrinfo(host, port, family, socket.SOCK_STREAM):
               ~~~~~~~~~~~~~~~~~~^^^^^^^^^^^^^^^^^^^^^^^^^^^^^^^^^^^^^^^^
  File "C:\Users\HP\AppData\Local\Programs\Python\Python313\Lib\socket.py", line 977, in getaddrinfo
    for res in _socket.getaddrinfo(host, port, family, type, proto, flags):
               ~~~~~~~~~~~~~~~~~~~^^^^^^^^^^^^^^^^^^^^^^^^^^^^^^^^^^^^^^^^
socket.gaierror: [Errno 11001] getaddrinfo failed

The above exception was the direct cause of the following exception:

Traceback (most recent call last):
  File "C:\Users\HP\Desktop\Arbitrage Betting\.venv\Lib\site-packages\urllib3\connectionpool.py", line 787, in urlopen
    response = self._make_request(
        conn,
    ...<10 lines>...
        **response_kw,
    )
  File "C:\Users\HP\Desktop\Arbitrage Betting\.venv\Lib\site-packages\urllib3\connectionpool.py", line 488, in _make_request
    raise new_e
  File "C:\Users\HP\Desktop\Arbitrage Betting\.venv\Lib\site-packages\urllib3\connectionpool.py", line 464, in _make_request
    self._validate_conn(conn)
    ~~~~~~~~~~~~~~~~~~~^^^^^^
  File "C:\Users\HP\Desktop\Arbitrage Betting\.venv\Lib\site-packages\urllib3\connectionpool.py", line 1093, in _validate_conn
    conn.connect()
    ~~~~~~~~~~~~^^
  File "C:\Users\HP\Desktop\Arbitrage Betting\.venv\Lib\site-packages\urllib3\connection.py", line 704, in connect
    self.sock = sock = self._new_conn()
                       ~~~~~~~~~~~~~~^^
  File "C:\Users\HP\Desktop\Arbitrage Betting\.venv\Lib\site-packages\urllib3\connection.py", line 205, in _new_conn
    raise NameResolutionError(self.host, self, e) from e
urllib3.exceptions.NameResolutionError: <urllib3.connection.HTTPSConnection object at 0x0000029D6C199590>: Failed to resolve '1xbet.com' ([Errno 11001] getaddrinfo failed)

The above exception was the direct cause of the following exception:

Traceback (most recent call last):
  File "C:\Users\HP\Desktop\Arbitrage Betting\.venv\Lib\site-packages\requests\adapters.py", line 667, in send
    resp = conn.urlopen(
        method=request.method,
    ...<9 lines>...
        chunked=chunked,
    )
  File "C:\Users\HP\Desktop\Arbitrage Betting\.venv\Lib\site-packages\urllib3\connectionpool.py", line 871, in urlopen
    return self.urlopen(
           ~~~~~~~~~~~~^
        method,
        ^^^^^^^
    ...<13 lines>...
        **response_kw,
        ^^^^^^^^^^^^^^
    )
    ^
  File "C:\Users\HP\Desktop\Arbitrage Betting\.venv\Lib\site-packages\urllib3\connectionpool.py", line 871, in urlopen
    return self.urlopen(
           ~~~~~~~~~~~~^
        method,
        ^^^^^^^
    ...<13 lines>...
        **response_kw,
        ^^^^^^^^^^^^^^
    )
    ^
  File "C:\Users\HP\Desktop\Arbitrage Betting\.venv\Lib\site-packages\urllib3\connectionpool.py", line 871, in urlopen
    return self.urlopen(
           ~~~~~~~~~~~~^
        method,
        ^^^^^^^
    ...<13 lines>...
        **response_kw,
        ^^^^^^^^^^^^^^
    )
    ^
  [Previous line repeated 7 more times]
  File "C:\Users\HP\Desktop\Arbitrage Betting\.venv\Lib\site-packages\urllib3\connectionpool.py", line 841, in urlopen
    retries = retries.increment(
        method, url, error=new_e, _pool=self, _stacktrace=sys.exc_info()[2]
    )
  File "C:\Users\HP\Desktop\Arbitrage Betting\.venv\Lib\site-packages\urllib3\util\retry.py", line 519, in increment
    raise MaxRetryError(_pool, url, reason) from reason  # type: ignore[arg-type]
    ^^^^^^^^^^^^^^^^^^^^^^^^^^^^^^^^^^^^^^^^^^^^^^^^^^^
urllib3.exceptions.MaxRetryError: HTTPSConnectionPool(host='1xbet.com', port=443): Max retries exceeded with url: /LiveFeed/GetChampsZip?sport=1&lng=en&country=187&partner=213&virtualSports=true&groupChamps=true (Caused by NameResolutionError("<urllib3.connection.HTTPSConnection object at 0x0000029D6C199590>: Failed to resolve '1xbet.com' ([Errno 11001] getaddrinfo failed)"))

During handling of the above exception, another exception occurred:

Traceback (most recent call last):
  File "C:\Users\HP\Desktop\Arbitrage Betting\Football\1xbet Scraper\1xbet_scraper.py", line 389, in <module>
    main()
    ~~~~^^
  File "C:\Users\HP\Desktop\Arbitrage Betting\Football\1xbet Scraper\1xbet_scraper.py", line 325, in main
    leagues_by_country, country_map = get_country_leagues(session)
                                      ~~~~~~~~~~~~~~~~~~~^^^^^^^^^
  File "C:\Users\HP\Desktop\Arbitrage Betting\Football\1xbet Scraper\1xbet_scraper.py", line 147, in get_country_leagues
    r = session.get(CHAMPS_URL, params=CHAMPS_PARAMS, timeout=REQUEST_TIMEOUT)
  File "C:\Users\HP\Desktop\Arbitrage Betting\.venv\Lib\site-packages\requests\sessions.py", line 602, in get
    return self.request("GET", url, **kwargs)
           ~~~~~~~~~~~~^^^^^^^^^^^^^^^^^^^^^^
  File "C:\Users\HP\Desktop\Arbitrage Betting\.venv\Lib\site-packages\requests\sessions.py", line 589, in request
    resp = self.send(prep, **send_kwargs)
  File "C:\Users\HP\Desktop\Arbitrage Betting\.venv\Lib\site-packages\requests\sessions.py", line 703, in send
    r = adapter.send(request, **kwargs)
  File "C:\Users\HP\Desktop\Arbitrage Betting\.venv\Lib\site-packages\requests\adapters.py", line 700, in send
    raise ConnectionError(e, request=request)
requests.exceptions.ConnectionError: HTTPSConnectionPool(host='1xbet.com', port=443): Max retries exceeded with url: /LiveFeed/GetChampsZip?sport=1&lng=en&country=187&partner=213&virtualSports=true&groupChamps=true (Caused by NameResolutionError("<urllib3.connection.HTTPSConnection object at 0x0000029D6C199590>: Failed to resolve '1xbet.com' ([Errno 11001] getaddrinfo failed)"))

Process finished with exit code 1
